Workbook
Name IQ_CH: 110000
Name IQ_CQ: 5000
Name IQ_CY: 10000
Name IQ_DAILY: 500000
Name IQ_FH: 100000
Name IQ_FQ: 500
Name IQ_FY: 1000
Name IQ_LTM: 2000
Name IQ_MONTH: 15000
Name IQ_NTM: 6000
Name IQ_WEEK: 50000
Name IQ_YTD: 3000
Name UPDATE: 'Data Sheet'!$E$1

Sheet Financials>
B2: =" Historical Financial Statement-" & 'Data Sheet'!B1 -> Historical Financial Statement-INFOSYS LTD
B3: Years | C3: ='Data Sheet'!B16 -> 42825 | D3: ='Data Sheet'!C16 -> 43190 | E3: ='Data Sheet'!D16 -> 43555 | F3: ='Data Sheet'!E16 -> 43921 | G3: ='Data Sheet'!F16 -> 44286 | H3: ='Data Sheet'!G16 -> 44651 | I3: ='Data Sheet'!H16 -> 45016 | J3: ='Data Sheet'!I16 -> 45382 | ... L3: ='Data Sheet'!K16 -> 46112 | M3: LTM
A4: # | B4: Income Statement
B5: Sales | C5: =IFERROR('Data Sheet'!B17,0) -> 68484 | D5: =IFERROR('Data Sheet'!C17,0) -> 70522 | E5: =IFERROR('Data Sheet'!D17,0) -> 82675 | F5: =IFERROR('Data Sheet'!E17,0) -> 90791 | G5: =IFERROR('Data Sheet'!F17,0) -> 100472 | H5: =IFERROR('Data Sheet'!G17,0) -> 121641 | I5: =IFERROR('Data Sheet'!H17,0) -> 146767 | J5: =IFERROR('Data Sheet'!I17,0) -> 153670 | ... L5: =IFERROR('Data Sheet'!K17,0) -> 178650 | M5: =IFERROR(SUM('Data Sheet'!H42:K42),0) -> 178650
B6: Sales Growth | C6: - | D6: =D5/C5-1 -> 0.029758776 | E6: =E5/D5-1 -> 0.1723292 | F6: =F5/E5-1 -> 0.098167523 | G6: =G5/F5-1 -> 0.10662951 | H6: =H5/G5-1 -> 0.21069552 | I6: =I5/H5-1 -> 0.20655864 | J6: =J5/I5-1 -> 0.047033734 | K6: =K5/J5-1 -> 0.060649444 | ... M6: =M5/L5-1 -> 0
B8: COGS | C8: =IFERROR(SUM('Data Sheet'!B18,'Data Sheet'!B20:B22)-1*'Data Sheet'!B19,) -> 44609 | D8: =IFERROR(SUM('Data Sheet'!C18,'Data Sheet'!C20:C22)-1*'Data Sheet'!C19,) -> 46395 | E8: =IFERROR(SUM('Data Sheet'!D18,'Data Sheet'!D20:D22)-1*'Data Sheet'!D19,) -> 55446 | F8: =IFERROR(SUM('Data Sheet'!E18,'Data Sheet'!E20:E22)-1*'Data Sheet'!E19,) -> 62210 | G8: =IFERROR(SUM('Data Sheet'!F18,'Data Sheet'!F20:F22)-1*'Data Sheet'!F19,) -> 68490 | H8: =IFERROR(SUM('Data Sheet'!G18,'Data Sheet'!G20:G22)-1*'Data Sheet'!G19,) -> 84819 | I8: =IFERROR(SUM('Data Sheet'!H18,'Data Sheet'!H20:H22)-1*'Data Sheet'!H19,) -> 104880 | J8: =IFERROR(SUM('Data Sheet'!I18,'Data Sheet'!I20:I22)-1*'Data Sheet'!I19,) -> 110030 | ... L8: =IFERROR(SUM('Data Sheet'!K18,'Data Sheet'!K20:K22)-1*'Data Sheet'!K19,) -> 128257 | M8: =IFERROR(SUM('Data Sheet'!H43:K43),0) -> 136371
B9: COGS % Sales | C9: =C8/C5 -> 0.65137842 | D9: =D8/D5 -> 0.65787981 | E9: =E8/E5 -> 0.67065014 | F9: =F8/F5 -> 0.68520007 | G9: =G8/G5 -> 0.68168246 | H9: =H8/H5 -> 0.69728957 | I9: =I8/I5 -> 0.71460206 | J9: =J8/J5 -> 0.71601484 | ... M9: =M8/M5 -> 0.76334173
B11: Gross Profit | C11: =C5-C8 -> 23875 | D11: =D5-D8 -> 24127 | E11: =E5-E8 -> 27229 | F11: =F5-F8 -> 28581 | G11: =G5-G8 -> 31982 | H11: =H5-H8 -> 36822 | I11: =I5-I8 -> 41887 | J11: =J5-J8 -> 43640 | ... M11: =M5-M8 -> 42279
B12: Gross Margin | C12: =C11/C5 -> 0.34862158 | D12: =D11/D5 -> 0.34212019 | E12: =E11/E5 -> 0.32934986 | F12: =F11/F5 -> 0.31479993 | G12: =G11/G5 -> 0.31831754 | H12: =H11/H5 -> 0.30271043 | I12: =I11/I5 -> 0.28539794 | J12: =J11/J5 -> 0.28398516 | ... M12: =M11/M5 -> 0.23665827
B14: Selling & General Expenses | C14: =IFERROR(SUM('Data Sheet'!B23:B24),0) -> 5271 | D14: =IFERROR(SUM('Data Sheet'!C23:C24),0) -> 5305 | E14: =IFERROR(SUM('Data Sheet'!D23:D24),0) -> 7059 | F14: =IFERROR(SUM('Data Sheet'!E23:E24),0) -> 6314 | G14: =IFERROR(SUM('Data Sheet'!F23:F24),0) -> 4093 | H14: =IFERROR(SUM('Data Sheet'!G23:G24),0) -> 5331 | I14: =IFERROR(SUM('Data Sheet'!H23:H24),0) -> 6757 | J14: =IFERROR(SUM('Data Sheet'!I23:I24),0) -> 7215 | ... L14: =IFERROR(SUM('Data Sheet'!K23:K24),0) -> 8113
B15: S&G Exp % Sales | C15: =C14/C5 -> 0.076966883 | D15: =D14/D5 -> 0.075224753 | E15: =E14/E5 -> 0.085382522 | F15: =F14/F5 -> 0.069544338 | G15: =G14/G5 -> 0.040737718 | H15: =H14/H5 -> 0.043825684 | I15: =I14/I5 -> 0.04603896 | J15: =J14/J5 -> 0.046951259 | ... L15: =L14/L5 -> 0.045412818
B17: EBITDA | C17: =C11-C14 -> 18604 | D17: =D11-D14 -> 18822 | E17: =E11-E14 -> 20170 | F17: =F11-F14 -> 22267 | G17: =G11-G14 -> 27889 | H17: =H11-H14 -> 31491 | I17: =I11-I14 -> 35130 | J17: =J11-J14 -> 36425 | ... L17: =L11-L14 -> 42280 | M17: =IFERROR(SUM('Data Sheet'!H51:K51),0) -> 45278
B18: EBITDA Margins | C18: =C17/C5 -> 0.27165469 | D18: =D17/D5 -> 0.26689544 | E18: =E17/E5 -> 0.24396734 | F18: =F17/F5 -> 0.24525559 | G18: =G17/G5 -> 0.27757982 | H18: =H17/H5 -> 0.25888475 | I18: =I17/I5 -> 0.23935898 | J18: =J17/J5 -> 0.2370339 | ... M18: =M17/M5 -> 0.25344528
B20: Interest | C20: =IFERROR('Data Sheet'!B27,0) -> 0 | D20: =IFERROR('Data Sheet'!C27,0) -> 0 | E20: =IFERROR('Data Sheet'!D27,0) -> 0 | F20: =IFERROR('Data Sheet'!E27,0) -> 170 | G20: =IFERROR('Data Sheet'!F27,0) -> 195 | H20: =IFERROR('Data Sheet'!G27,0) -> 200 | I20: =IFERROR('Data Sheet'!H27,0) -> 284 | J20: =IFERROR('Data Sheet'!I27,0) -> 470 | ... L20: =IFERROR('Data Sheet'!K27,0) -> 416 | M20: =IFERROR(SUM('Data Sheet'!H46:K46),0) -> 416
B21: Interest % Sales | C21: =C20/C5 -> 0 | D21: =D20/D5 -> 0 | E21: =E20/E5 -> 0 | F21: =F20/F5 -> 0.0018724323 | G21: =G20/G5 -> 0.0019408392 | H21: =H20/H5 -> 0.0016441825 | I21: =I20/I5 -> 0.0019350399 | J21: =J20/J5 -> 0.003058502 | ... M21: =M20/M5 -> 0.0023285754
B23: Depreciation | C23: =IFERROR('Data Sheet'!B26,0) -> 1703 | D23: =IFERROR('Data Sheet'!C26,0) -> 1863 | E23: =IFERROR('Data Sheet'!D26,0) -> 2011 | F23: =IFERROR('Data Sheet'!E26,0) -> 2893 | G23: =IFERROR('Data Sheet'!F26,0) -> 3267 | H23: =IFERROR('Data Sheet'!G26,0) -> 3476 | I23: =IFERROR('Data Sheet'!H26,0) -> 4225 | J23: =IFERROR('Data Sheet'!I26,0) -> 4678 | ... L23: =IFERROR('Data Sheet'!K26,0) -> 4902 | M23: =IFERROR(SUM('Data Sheet'!H45:K45),0) -> 4901
B24: Depreciation%Sales | C24: =C23/C5 -> 0.024867122 | D24: =D23/D5 -> 0.026417288 | E24: =E23/E5 -> 0.024324161 | F24: =F23/F5 -> 0.031864392 | G24: =G23/G5 -> 0.032516522 | H24: =H23/H5 -> 0.028575891 | I24: =I23/I5 -> 0.028787125 | J24: =J23/J5 -> 0.030441856 | ... M24: =M23/M5 -> 0.027433529 | Q24: =Q15-(Q18+Q21) -> 0
B26: Earnings Before Tax | C26: =C17-(C20+C23) -> 16901 | D26: =D17-(D20+D23) -> 16959 | E26: =E17-(E20+E23) -> 18159 | F26: =F17-(F20+F23) -> 19204 | G26: =G17-(G20+G23) -> 24427 | H26: =H17-(H20+H23) -> 27815 | I26: =I17-(I20+I23) -> 30621 | J26: =J17-(J20+J23) -> 31277 | ... M26: =M17-(M20+M23) -> 39961
B27: EBT % Sales | C27: =C26/C5 -> 0.24678757 | D27: =D26/D5 -> 0.24047815 | E27: =E26/E5 -> 0.21964318 | F27: =F26/F5 -> 0.21151876 | G27: =G26/G5 -> 0.24312246 | H27: =H26/H5 -> 0.22866468 | I27: =I26/I5 -> 0.20863682 | J27: =J26/J5 -> 0.20353355 | ... M27: =M26/M5 -> 0.22368318
B29: Tax | C29: =IFERROR('Data Sheet'!B29,0) -> 5598 | D29: =IFERROR('Data Sheet'!C29,0) -> 4241 | E29: =IFERROR('Data Sheet'!D29,0) -> 5631 | F29: =IFERROR('Data Sheet'!E29,0) -> 5368 | G29: =IFERROR('Data Sheet'!F29,0) -> 7205 | H29: =IFERROR('Data Sheet'!G29,0) -> 7964 | I29: =IFERROR('Data Sheet'!H29,0) -> 9214 | J29: =IFERROR('Data Sheet'!I29,0) -> 9740 | ... L29: =IFERROR('Data Sheet'!K29,0) -> 10521 | M29: =IFERROR(SUM('Data Sheet'!H48:K48),0) -> 10521
B30: Effective Tax Rate | C30: =C29/C26 -> 0.331223 | D30: =D29/D26 -> 0.25007371 | E30: =E29/E26 -> 0.31009417 | F30: =F29/F26 -> 0.2795251 | G30: =G29/G26 -> 0.29496049 | H30: =H29/H26 -> 0.28632033 | I30: =I29/I26 -> 0.30090461 | J30: =J29/J26 -> 0.31141094 | ... M30: =M29/M26 -> 0.2632817
B32: Net Profit | C32: =C26-C29 -> 11303 | D32: =D26-D29 -> 12718 | E32: =E26-E29 -> 12528 | F32: =F26-F29 -> 13836 | G32: =G26-G29 -> 17222 | H32: =H26-H29 -> 19851 | I32: =I26-I29 -> 21407 | J32: =J26-J29 -> 21537 | ... M32: =M26-M29 -> 29440
B33: Net Margins | C33: =C32/C5 -> 0.16504585 | D33: =D32/D5 -> 0.18034089 | E33: =E32/E5 -> 0.15153311 | F33: =F32/F5 -> 0.15239396 | G33: =G32/G5 -> 0.17141094 | H33: =H32/H5 -> 0.16319333 | I33: =I32/I5 -> 0.14585704 | J33: =J32/J5 -> 0.14015097 | ... M33: =M32/M5 -> 0.16479149
B35: No of Equity Shares | C35: =IFERROR('Data Sheet'!B93,0) -> 459.39 | D35: =IFERROR('Data Sheet'!C93,0) -> 436.82 | E35: =IFERROR('Data Sheet'!D93,0) -> 436.89 | F35: =IFERROR('Data Sheet'!E93,0) -> 425.9 | G35: =IFERROR('Data Sheet'!F93,0) -> 426.07 | H35: =IFERROR('Data Sheet'!G93,0) -> 420.67 | I35: =IFERROR('Data Sheet'!H93,0) -> 414.86 | J35: =IFERROR('Data Sheet'!I93,0) -> 415.09 | ... M35: =IFERROR('Data Sheet'!L93,0) -> 0
B36: In crores
B37: EPS | C37: =C32/C35 -> 24.604367 | D37: =D32/D35 -> 29.114967 | E37: =E32/E35 -> 28.67541 | F37: =F32/F35 -> 32.486499 | G37: =G32/G35 -> 40.420588 | H37: =H32/H35 -> 47.189008 | I37: =I32/I35 -> 51.60054 | J37: =J32/J35 -> 51.885133 | ... L37: =L32/L35 -> 65.196272 | M37: -
B38: EPS Growth % | D38: =D37/C37-1 -> 0.18332521 | E38: =E37/D37-1 -> -0.015097286 | F38: =F37/E37-1 -> 0.13290442 | G38: =G37/F37-1 -> 0.24422727 | H38: =H37/G37-1 -> 0.16744981 | I38: =I37/H37-1 -> 0.093486431 | J38: =J37/I37-1 -> 0.0055153183 | K38: =K37/J37-1 -> 0.074273236 | L38: =L37/K37-1 -> 0.16967463 | M38: -
B40: Dividend per Share | C40: =IFERROR('Data Sheet'!B31/'Data Sheet'!B93,0) -> 12.824833 | D40: =IFERROR('Data Sheet'!C31/'Data Sheet'!C93,0) -> 21.669337 | E40: =IFERROR('Data Sheet'!D31/'Data Sheet'!D93,0) -> 21.109433 | F40: =IFERROR('Data Sheet'!E31/'Data Sheet'!E93,0) -> 17.438366 | G40: =IFERROR('Data Sheet'!F31/'Data Sheet'!F93,0) -> 26.91952 | H40: =IFERROR('Data Sheet'!G31/'Data Sheet'!G93,0) -> 30.92115 | I40: =IFERROR('Data Sheet'!H31/'Data Sheet'!H93,0) -> 33.913127 | J40: =IFERROR('Data Sheet'!I31/'Data Sheet'!I93,0) -> 45.901371 | ... L40: =IFERROR('Data Sheet'!K31/'Data Sheet'!K93,0) -> 47.91005 | M40: -
B41: Dividend payout ratio | C41: =C40/C37 -> 0.52124215 | D41: =D40/D37 -> 0.74426797 | E41: =E40/E37 -> 0.73615102 | F41: =F40/F37 -> 0.53678809 | G41: =G40/G37 -> 0.66598537 | H41: =H40/H37 -> 0.6552617 | I41: =I40/I37 -> 0.65722427 | J41: =J40/J37 -> 0.88467289 | ... L41: =L40/L37 -> 0.73485874 | M41: =-G44 -> 0
B43: Retained Earnings | C43: =IFERROR(IF(C37>C40,1-C41,0),0) -> 0.47875785 | D43: =IFERROR(IF(D37>D40,1-D41,0),0) -> 0.25573203 | E43: =IFERROR(IF(E37>E40,1-E41,0),0) -> 0.26384898 | F43: =IFERROR(IF(F37>F40,1-F41,0),0) -> 0.46321191 | G43: =IFERROR(IF(G37>G40,1-G41,0),0) -> 0.33401463 | H43: =IFERROR(IF(H37>H40,1-H41,0),0) -> 0.3447383 | I43: =IFERROR(IF(I37>I40,1-I41,0),0) -> 0.34277573 | J43: =IFERROR(IF(J37>J40,1-J41,0),0) -> 0.11532711 | ... M43: =IFERROR(IF(M37>M40,1-M41,0),0) -> 0
A46: # | B46: Balance Sheet
B47: Equity Share Capital | C47: =IFERROR('Data Sheet'!B57,0) -> 1144 | D47: =IFERROR('Data Sheet'!C57,0) -> 1088 | E47: =IFERROR('Data Sheet'!D57,0) -> 2170 | F47: =IFERROR('Data Sheet'!E57,0) -> 2122 | G47: =IFERROR('Data Sheet'!F57,0) -> 2124 | H47: =IFERROR('Data Sheet'!G57,0) -> 2098 | I47: =IFERROR('Data Sheet'!H57,0) -> 2069 | J47: =IFERROR('Data Sheet'!I57,0) -> 2071 | ... L47: =IFERROR('Data Sheet'!K57,0) -> 2024
B48: Reserves | C48: =IFERROR('Data Sheet'!B58,0) -> 67838 | D48: =IFERROR('Data Sheet'!C58,0) -> 63835 | E48: =IFERROR('Data Sheet'!D58,0) -> 62778 | F48: =IFERROR('Data Sheet'!E58,0) -> 63328 | G48: =IFERROR('Data Sheet'!F58,0) -> 74227 | H48: =IFERROR('Data Sheet'!G58,0) -> 73252 | I48: =IFERROR('Data Sheet'!H58,0) -> 73338 | J48: =IFERROR('Data Sheet'!I58,0) -> 86045 | ... L48: =IFERROR('Data Sheet'!K58,0) -> 90828
B49: Borrowings | C49: =IFERROR('Data Sheet'!B59,0) -> 0 | D49: =IFERROR('Data Sheet'!C59,0) -> 0 | E49: =IFERROR('Data Sheet'!D59,0) -> 0 | F49: =IFERROR('Data Sheet'!E59,0) -> 4633 | G49: =IFERROR('Data Sheet'!F59,0) -> 5325 | H49: =IFERROR('Data Sheet'!G59,0) -> 5474 | I49: =IFERROR('Data Sheet'!H59,0) -> 8299 | J49: =IFERROR('Data Sheet'!I59,0) -> 8359 | ... L49: =IFERROR('Data Sheet'!K59,0) -> 9176
B50: Other Liabilities | C50: =IFERROR('Data Sheet'!B60,0) -> 14166 | D50: =IFERROR('Data Sheet'!C60,0) -> 14426 | E50: =IFERROR('Data Sheet'!D60,0) -> 19118 | F50: =IFERROR('Data Sheet'!E60,0) -> 21717 | G50: =IFERROR('Data Sheet'!F60,0) -> 25835 | H50: =IFERROR('Data Sheet'!G60,0) -> 35905 | I50: =IFERROR('Data Sheet'!H60,0) -> 40890 | J50: =IFERROR('Data Sheet'!I60,0) -> 40885 | ... L50: =IFERROR('Data Sheet'!K60,0) -> 52260
B51: Total Liabilities | C51: =IFERROR('Data Sheet'!B61,0) -> 83148 | D51: =IFERROR('Data Sheet'!C61,0) -> 79349 | E51: =IFERROR('Data Sheet'!D61,0) -> 84066 | F51: =IFERROR('Data Sheet'!E61,0) -> 91800 | G51: =IFERROR('Data Sheet'!F61,0) -> 107511 | H51: =IFERROR('Data Sheet'!G61,0) -> 116729 | I51: =IFERROR('Data Sheet'!H61,0) -> 124596 | J51: =IFERROR('Data Sheet'!I61,0) -> 137360 | ... L51: =IFERROR('Data Sheet'!K61,0) -> 154288
B53: Fixed Assests Net Block | C53: =IFERROR('Data Sheet'!B62,0) -> 14179 | D53: =IFERROR('Data Sheet'!C62,0) -> 12574 | E53: =IFERROR('Data Sheet'!D62,0) -> 15710 | F53: =IFERROR('Data Sheet'!E62,0) -> 23789 | G53: =IFERROR('Data Sheet'!F62,0) -> 25505 | H53: =IFERROR('Data Sheet'!G62,0) -> 25800 | I53: =IFERROR('Data Sheet'!H62,0) -> 29225 | J53: =IFERROR('Data Sheet'!I62,0) -> 27622 | ... L53: =IFERROR('Data Sheet'!K62,0) -> 33770
B54: Capital Work in Progress | C54: =IFERROR('Data Sheet'!B63,0) -> 1365 | D54: =IFERROR('Data Sheet'!C63,0) -> 1606 | E54: =IFERROR('Data Sheet'!D63,0) -> 1388 | F54: =IFERROR('Data Sheet'!E63,0) -> 954 | G54: =IFERROR('Data Sheet'!F63,0) -> 922 | H54: =IFERROR('Data Sheet'!G63,0) -> 416 | I54: =IFERROR('Data Sheet'!H63,0) -> 288 | J54: =IFERROR('Data Sheet'!I63,0) -> 293 | ... L54: =IFERROR('Data Sheet'!K63,0) -> 526
B55: Investments | C55: =IFERROR('Data Sheet'!B64,0) -> 16423 | D55: =IFERROR('Data Sheet'!C64,0) -> 12163 | E55: =IFERROR('Data Sheet'!D64,0) -> 11261 | F55: =IFERROR('Data Sheet'!E64,0) -> 8792 | G55: =IFERROR('Data Sheet'!F64,0) -> 14205 | H55: =IFERROR('Data Sheet'!G64,0) -> 20324 | I55: =IFERROR('Data Sheet'!H64,0) -> 19478 | J55: =IFERROR('Data Sheet'!I64,0) -> 24623 | ... L55: =IFERROR('Data Sheet'!K64,0) -> 21880
B56: Other Assets | C56: =IFERROR('Data Sheet'!B65-SUM('Data Sheet'!B67:B69,0),0) -> 16234 | D56: =IFERROR('Data Sheet'!C65-SUM('Data Sheet'!C67:C69,0),0) -> 20046 | E56: =IFERROR('Data Sheet'!D65-SUM('Data Sheet'!D67:D69,0),0) -> 21312 | F56: =IFERROR('Data Sheet'!E65-SUM('Data Sheet'!E67:E69,0),0) -> 21129 | G56: =IFERROR('Data Sheet'!F65-SUM('Data Sheet'!F67:F69,0),0) -> 22871 | H56: =IFERROR('Data Sheet'!G65-SUM('Data Sheet'!G67:G69,0),0) -> 30019 | I56: =IFERROR('Data Sheet'!H65-SUM('Data Sheet'!H67:H69,0),0) -> 38008 | J56: =IFERROR('Data Sheet'!I65-SUM('Data Sheet'!I67:I69,0),0) -> 39843 | ... L56: =IFERROR('Data Sheet'!K65-SUM('Data Sheet'!K67:K69,0),0) -> 40677
...

Sheet Cash Flow Data
C2: 40603 | D2: 40969 | E2: 41334 | F2: 41699 | G2: 42064 | H2: 42430 | I2: 42795 | J2: 43160 | K2: 43525 | L2: 43891 | M2: 44256 | N2: 44621
B3: Cash from Operating Activity - | C3: 11240 | D3: 18384 | E3: 22163 | F3: 36151 | G3: 35531 | H3: 37900 | I3: 30199 | J3: 23857 | K3: 18891 | L3: 26633 | M3: 29001 | N3: 14283
B4: Profit from operations | C4: 16680 | D4: 22432 | E4: 24406 | F4: 36303 | G4: 43397 | H4: 38626 | I4: 28840 | J4: 33312 | K4: 28771 | L4: 23352 | M4: 31198 | N4: 26666
B5: Receivables | C5: -1422 | D5: -6659 | E5: -5177 | F5: 445 | G5: -3179 | H5: -2223 | I5: -4152 | J5: -10688 | K5: -9109 | L5: 9950 | M5: -5505 | N5: 337
B6: Inventory | C6: -2411 | D6: -2719 | E6: -2656 | F6: -2853 | G6: -3692 | H6: -5743 | I6: -6621 | J6: -3560 | K6: 2069 | L6: 2326 | M6: 3814 | N6: 597
B7: Payables | C7: 344 | D7: 5867 | E7: 8132 | F7: 4694 | G7: 3598 | H7: 3947 | I7: 9301 | J7: 7320 | K7: -4692 | L7: -8085 | M7: 5748 | N7: -7012
B8: Loans Advances | C8: 0 | D8: 0 | E8: 0 | F8: 0 | G8: 0 | H8: -520 | I8: 0 | J8: 0 | K8: 0 | L8: 0 | M8: 0 | N8: 0
B9: Other WC items | C9: -559 | D9: 1231 | E9: -303 | F9: 1870 | G9: -398 | H9: 5852 | I9: 4727 | J9: 494 | K9: 4512 | L9: 875 | M9: -4150 | N9: -4396
B10: Working capital changes | C10: -4048 | D10: -2280 | E10: -3 | F10: 4157 | G10: -3672 | H10: 1313 | I10: 3254 | J10: -6434 | K10: -7221 | L10: 5065 | M10: -93 | N10: -10474
B11: Direct taxes | C11: -1391 | D11: -1768 | E11: -2240 | F11: -4308 | G11: -4194 | H11: -2040 | I11: -1895 | J11: -3021 | K11: -2659 | L11: -1785 | M11: -2105 | N11: -1910
B12: Cash from Investing Activity - | C12: -7023 | D12: -19464 | E12: -22969 | F12: -27991 | G12: -36232 | H12: -36694 | I12: -39571 | J12: -25139 | K12: -20878 | L12: -33115 | M12: -25672 | N12: -4444
B13: Fixed assets purchased | C13: -8124 | D13: -13876 | E13: -18863 | F13: -26975 | G13: -31962 | H13: -31503 | I13: -16072 | J13: -35079 | K13: -35304 | L13: -29702 | M13: -20205 | N13: -15168
B14: Fixed assets sold | C14: 11 | D14: 93 | E14: 37 | F14: 50 | G14: 74 | H14: 59 | I14: 53 | J14: 30 | K14: 67 | L14: 171 | M14: 351 | N14: 230
... B35: Net Cash Flow | C35: 2815 | D35: 5488 | E35: -2499 | F35: 4277 | G35: 4500 | H35: -2589 | I35: -3167 | J35: 730 | K35: 6843 | L35: -3092 | M35: 13232 | N35: 6459

Sheet Data Sheet
A1: COMPANY NAME | B1: INFOSYS LTD | E1: =IF(B2<>B3, "A NEW VERSION OF THE WORKSHEET IS AVAILABLE", "")
A2: LATEST VERSION | B2: 2.1 | E2: PLEASE DO NOT MAKE ANY CHANGES TO THIS SHEET
A3: CURRENT VERSION | B3: 2.1
A5: META
A6: Number of shares | B6: =IF(B9>0, B9/B8, 0) -> 405.41143
A7: Face Value | B7: 5
A8: Current Price | B8: 1174.5
A9: Market Capitalization | B9: 476155.72
A15: PROFIT & LOSS | B15: =B26+B34 -> 23357 | K15: =K17-K18-K20-K21-K22-K23-K19 -> 43609
A16: Report Date | B16: 42825 | C16: 43190 | D16: 43555 | E16: 43921 | F16: 44286 | G16: 44651 | H16: 45016 | I16: 45382 | J16: 45747 | K16: 46112
A17: Sales | B17: 68484 | C17: 70522 | D17: 82675 | E17: 90791 | F17: 100472 | G17: 121641 | H17: 146767 | I17: 153670 | J17: 162990 | K17: 178650
A18: Raw Material Cost
A19: Change in Inventory
A20: Power and Fuel | B20: 228 | C20: 207 | D20: 221 | E20: 229 | F20: 143 | G20: 132 | H20: 176 | I20: 199 | J20: 222 | K20: 223
A21: Other Mfr. Exp | B21: 6712 | C21: 7286 | D21: 9902 | E21: 11086 | F21: 12800 | G21: 20690 | H21: 26330 | I21: 27195 | J21: 30395 | K21: 32922
A22: Employee Cost | B22: 37669 | C22: 38902 | D22: 45323 | E22: 50895 | F22: 55547 | G22: 63997 | H22: 78374 | I22: 82636 | J22: 85968 | K22: 95112
A23: Selling and admin | B23: 4584 | C23: 4585 | D23: 5553 | E23: 5375 | F23: 3194 | G23: 4305 | H23: 5300 | I23: 5705 | J23: 6039 | K23: 6784
A24: Other Expenses | B24: 687 | C24: 720 | D24: 1506 | E24: 939 | F24: 899 | G24: 1026 | H24: 1457 | I24: 1510 | J24: 1130 | K24: 1329
A25: Other Income | B25: 3050 | C25: 3311 | D25: 2882 | E25: 2803 | F25: 2201 | G25: 2295 | H25: 2701 | I25: 4711 | J25: 3600 | K25: 3033
A26: Depreciation | B26: 1703 | C26: 1863 | D26: 2011 | E26: 2893 | F26: 3267 | G26: 3476 | H26: 4225 | I26: 4678 | J26: 4812 | K26: 4902
A27: Interest | E27: 170 | F27: 195 | G27: 200 | H27: 284 | I27: 470 | J27: 416 | K27: 416
A28: Profit before tax | B28: 19951 | C28: 20270 | D28: 21041 | E28: 22007 | F28: 26628 | G28: 30110 | H28: 33322 | I28: 35988 | J28: 37608 | K28: 39995
A29: Tax | B29: 5598 | C29: 4241 | D29: 5631 | E29: 5368 | F29: 7205 | G29: 7964 | H29: 9214 | I29: 9740 | J29: 10858 | K29: 10521
A30: Net profit | B30: 14353 | C30: 16029 | D30: 15404 | E30: 16594 | F30: 19351 | G30: 22110 | H30: 24095 | I30: 26233 | J30: 26713 | K30: 29440
A31: Dividend Amount | B31: 5891.6 | C31: 9465.6 | D31: 9222.5 | E31: 7427 | F31: 11469.6 | G31: 13007.6 | H31: 14069.2 | I31: 19053.2 | J31: 17827.8 | K31: 19430.4
A32: Effective Tax Rate | B32: =B29/B28 -> 0.28058744 | C32: =C29/C28 -> 0.20922546 | D32: =D29/D28 -> 0.26762036 | E32: =E29/E28 -> 0.24392239 | F32: =F29/F28 -> 0.27057984 | G32: =G29/G28 -> 0.26449684 | H32: =H29/H28 -> 0.27651401 | I32: =I29/I28 -> 0.27064577 | ... K32: =K29/K28 -> 0.26305788
A34: EBITDA | B34: =+B30+B29+B27+B26 -> 21654 | C34: =+C30+C29+C27+C26 -> 22133 | D34: =+D30+D29+D27+D26 -> 23046 | E34: =+E30+E29+E27+E26 -> 25025 | F34: =+F30+F29+F27+F26 -> 30018 | G34: =+G30+G29+G27+G26 -> 33750 | H34: =+H30+H29+H27+H26 -> 37818 | I34: =+I30+I29+I27+I26 -> 41121 | ... K34: =+K30+K29+K27+K26 -> 45279
A40: Quarters
A41: Report Date | B41: 45291 | C41: 45382 | D41: 45473 | E41: 45565 | F41: 45657 | G41: 45747 | H41: 45838 | I41: 45930 | J41: 46022 | K41: 46112
A42: Sales | B42: 38821 | C42: 37923 | D42: 39315 | E42: 40986 | F42: 41764 | G42: 40925 | H42: 42279 | I42: 44490 | J42: 45479 | K42: 46402
A43: Expenses | B43: 29684 | C43: 29139 | D43: 29878 | E43: 31177 | F43: 31649 | G43: 31051 | H43: 32336 | I43: 33955 | J43: 34845 | K43: 35235
A44: Other Income | B44: 789 | C44: 2729 | D44: 838 | E44: 712 | F44: 859 | G44: 1190 | H44: 1042 | I44: 982 | J44: -150 | K44: 1159
A45: Depreciation | B45: 1176 | C45: 1163 | D45: 1149 | E45: 1160 | F45: 1203 | G45: 1299 | H45: 1140 | I45: 1182 | J45: 1155 | K45: 1424
A46: Interest | B46: 131 | C46: 110 | D46: 105 | E46: 108 | F46: 101 | G46: 102 | H46: 105 | I46: 106 | J46: 100 | K46: 105
A47: Profit before tax | B47: 8619 | C47: 10240 | D47: 9021 | E47: 9253 | F47: 9670 | G47: 9663 | H47: 9740 | I47: 10229 | J47: 9229 | K47: 10797
A48: Tax | B48: 2506 | C48: 2265 | D48: 2647 | E48: 2737 | F48: 2848 | G48: 2625 | H48: 2816 | I48: 2854 | J48: 2563 | K48: 2288
A49: Net profit | B49: 6106 | C49: 7969 | D49: 6368 | E49: 6506 | F49: 6806 | G49: 7033 | H49: 6921 | I49: 7364 | J49: 6654 | K49: 8501
A50: Operating Profit | B50: 9137 | C50: 8784 | D50: 9437 | E50: 9809 | F50: 10115 | G50: 9874 | H50: 9943 | I50: 10535 | J50: 10634 | K50: 11167
A51: EBITDA | B51: =B49+B48+B46+B45 -> 9919 | C51: =C49+C48+C46+C45 -> 11507 | D51: =D49+D48+D46+D45 -> 10269 | E51: =E49+E48+E46+E45 -> 10511 | F51: =F49+F48+F46+F45 -> 10958 | G51: =G49+G48+G46+G45 -> 11059 | H51: =H49+H48+H46+H45 -> 10982 | I51: =I49+I48+I46+I45 -> 11506 | ... K51: =K49+K48+K46+K45 -> 12318
A55: BALANCE SHEET
...

Sheet ASSUMPTIONS
B1: Infosys Ltd - Key Assumptions
B2: WACC (Discount Rate) | F2: 0.11 | G2: CAPM: Riskfree rate 6% , Market risk 12% with a beta of 0.75
B3: Terminal Growth Rate | F3: 0.05 | G3: Nominal growth rate of GDP in India
B4: Forecast Horizon (years) | F4: 5 years
B5: Revenue Growth – FY27 | F5: 0.11
B6: Revenue Growth – FY28 | F6: 0.1
B7: Revenue Growth – FY29 | F7: 0.09
B8: Revenue Growth – FY30 | F8: 0.08
B9: Revenue Growth – FY31 | F9: 0.07
B10: EBITDA Margin – FY27 | F10: 0.28
B11: EBITDA Margin – FY28 | F11: 0.285
B12: EBITDA Margin – FY29 | F12: 0.29
B13: EBITDA Margin – FY30 | F13: 0.295
B14: EBITDA Margin – FY31 | F14: 0.3
B15: Depreciation % of Revenue | F15: 0.029 | G15: Average of past 5 years
B16: CapEx % of Revenue | F16: 0.02
B17: Change in NWC % of Rev | F17: 0.01
B18: Effective Tax Rate | F18: 0.3 | G18: Average of past 5 years
B19: Net Debt (FY26, ₹ Cr) | F19: -13025 | G19: Cash>Debt, that's why negative value

Sheet DCF VALUATION
B1: DCF VALUATION - INFOSYS LTD (all values in Rs CR. except per share value) | Q1: Infosys Ltd - Key Assumptions
A2: # | B2: Line Item | C2: FY26A | D2: FY27E | E2: FY28E | F2: FY29E | G2: FY30E | H2: FY31E
B3: Revenue (₹ Cr) | C3: ='Financials>'!L5 -> 178650 | D3: =C3*(1+R6) -> 198301.5 | E3: =D3*(1+R7) -> 218131.65 | F3: =E3*(1+R8) -> 237763.5 | G3: =F3*(1+R9) -> 256784.58 | H3: =G3*(1+R10) -> 274759.5 | P3: # | Q3: WACC (Discount Rate) | R3: =ASSUMPTIONS!F2 -> 0.11
B4: Revenue Growth % | C4: ='Financials>'!L6 -> 0.096079514 | D4: =R6 -> 0.11 | E4: =R7 -> 0.1 | F4: =R8 -> 0.09 | G4: =R9 -> 0.08 | H4: =R10 -> 0.07 | Q4: Terminal Growth Rate | R4: =ASSUMPTIONS!F3 -> 0.05
B5: EBITDA (₹ Cr) | C5: ='Financials>'!L17 -> 42280 | D5: =D3*D6 -> 55524.42 | E5: =E3*E6 -> 62167.52 | F5: =F3*F6 -> 68951.415 | G5: =G3*G6 -> 75751.451 | H5: =H3*H6 -> 82427.85 | Q5: Forecast Horizon (years) | R5: =ASSUMPTIONS!F4 -> 5 years
B6: EBITDA Margin % | C6: ='Financials>'!L18 -> 0.23666387 | D6: =R11 -> 0.28 | E6: =R12 -> 0.285 | F6: =R13 -> 0.29 | G6: =R14 -> 0.295 | H6: =R15 -> 0.3 | Q6: Revenue Growth – FY27 | R6: =ASSUMPTIONS!F5 -> 0.11
B7: (-) Depreciation (₹ Cr) | C7: ='Financials>'!L23 -> 4902 | D7: =$R$16*D3 -> 5750.7435 | E7: =$R$16*E3 -> 6325.8179 | F7: =$R$16*F3 -> 6895.1415 | G7: =$R$16*G3 -> 7446.7528 | H7: =$R$16*H3 -> 7968.0255 | Q7: Revenue Growth – FY28 | R7: =ASSUMPTIONS!F6 -> 0.1
B8: EBIT (₹ Cr) | C8: ='DCF VALUATION'!C5-'DCF VALUATION'!C7 -> 37378 | D8: =D5-D7 -> 49773.677 | E8: =E5-E7 -> 55841.702 | F8: =F5-F7 -> 62056.273 | G8: =G5-G7 -> 68304.698 | H8: =H5-H7 -> 74459.824 | Q8: Revenue Growth – FY29 | R8: =ASSUMPTIONS!F7 -> 0.09
B9: NOPAT = EBIT×(1-Tax) | C9: =C8*(1-R19) -> 26164.6 | D9: =D8*(1-$R$19) -> 34841.574 | E9: =E8*(1-$R$19) -> 39089.192 | F9: =F8*(1-$R$19) -> 43439.391 | G9: =G8*(1-$R$19) -> 47813.288 | H9: =H8*(1-$R$19) -> 52121.877 | Q9: Revenue Growth – FY30 | R9: =ASSUMPTIONS!F8 -> 0.08
B10: (+) Depreciation (₹ Cr) | C10: ='Financials>'!L23 -> 4902 | D10: =D7 -> 5750.7435 | E10: =E7 -> 6325.8179 | F10: =F7 -> 6895.1415 | G10: =G7 -> 7446.7528 | H10: =H7 -> 7968.0255 | I10: =I7 -> 0 | Q10: Revenue Growth – FY31 | R10: =ASSUMPTIONS!F9 -> 0.07
B11: (-) CapEx (₹ Cr) | C11: =2%*C3 -> 3573 | D11: =$R$17*D3 -> 3966.03 | E11: =$R$17*E3 -> 4362.633 | F11: =$R$17*F3 -> 4755.27 | G11: =$R$17*G3 -> 5135.6916 | H11: =$R$17*H3 -> 5495.19 | Q11: EBITDA Margin – FY27 | R11: =ASSUMPTIONS!F10 -> 0.28
B12: (-) Chg in NWC (₹ Cr) | C12: =$R$18*C3 -> 1786.5 | D12: =$R$18*D3 -> 1983.015 | E12: =$R$18*E3 -> 2181.3165 | F12: =$R$18*F3 -> 2377.635 | G12: =$R$18*G3 -> 2567.8458 | H12: =$R$18*H3 -> 2747.595 | Q12: EBITDA Margin – FY28 | R12: =ASSUMPTIONS!F11 -> 0.285
B13: Free Cash Flow to Firm (FCFF) | C13: =C9+C10-C11-C12 -> 25707.1 | D13: =D9+D10-D11-D12 -> 34643.272 | E13: =E9+E10-E11-E12 -> 38871.06 | F13: =F9+F10-F11-F12 -> 43201.628 | G13: =G9+G10-G11-G12 -> 47556.504 | H13: =H9+H10-H11-H12 -> 51847.117 | Q13: EBITDA Margin – FY29 | R13: =ASSUMPTIONS!F12 -> 0.29
Q14: EBITDA Margin – FY30 | R14: =ASSUMPTIONS!F13 -> 0.295
A15: # | B15: Discounting and terminal value | Q15: EBITDA Margin – FY31 | R15: =ASSUMPTIONS!F14 -> 0.3
B16: Discount Factor (1/(1+WACC)^t) | C16: =(1/(1+$R$3)^0) -> 1 | D16: =(1/(1+$R$3)^1) -> 0.9009009 | E16: =(1/(1+$R$3)^2) -> 0.81162243 | F16: =(1/(1+$R$3)^3) -> 0.73119138 | G16: =(1/(1+$R$3)^4) -> 0.65873097 | H16: =(1/(1+$R$3)^5) -> 0.59345133 | Q16: Depreciation % of Revenue | R16: =ASSUMPTIONS!F15 -> 0.029
B17: PV of FCFF (₹ Cr) | C17: =C13*C16 -> 25707.1 | D17: =D13*D16 -> 31210.155 | E17: =E13*E16 -> 31548.624 | F17: =F13*F16 -> 31588.658 | G17: =G13*G16 -> 31326.942 | H17: =H13*H16 -> 30768.741 | Q17: CapEx % of Revenue | R17: =ASSUMPTIONS!F16 -> 0.02
B18: Sum of PV (FCFF) – 5 years | C18: =SUM(D17:H17) -> 156443.12 | Q18: Change in NWC % of Rev | R18: =ASSUMPTIONS!F17 -> 0.01
B19: Terminal FCFF (FY32E, ₹ Cr) | C19: =H13*(1+R4) -> 54439.473 | Q19: Effective Tax Rate | R19: =ASSUMPTIONS!F18 -> 0.3
B20: Terminal Value (Gordon Growth, ₹ Cr) | C20: =C19/(R3-R4) -> 907324.56 | Q20: Net Debt (FY26, ₹ Cr) | R20: =ASSUMPTIONS!F19 -> -13025
B21: PV of Terminal Value (₹ Cr) | C21: =C20/(1+R3)^5 -> 538452.96
A23: # | B23: Enterprise value, Equity value and Fair Value
B24: Enterprise Value (₹ Cr) | C24: =C21+C18 -> 694896.08
B25: (–) Net Debt (₹ Cr) | C25: =R20 -> -13025
B26: Equity Value (₹ Cr) | C26: =C24-C25 -> 707921.08
B27: Shares Outstanding (Crore) | C27: ='Data Sheet'!B6 -> 405.41143
B28: FAIR VALUE PER SHARE (₹) | C28: =C26/C27 -> 1746.1794
B29: Current Market Price (₹) | C29: ='Data Sheet'!B8 -> 1174.5
B30: Upside / (Downside) vs CMP | C30: =(C28-C29)/C29 -> 0.48674279
B31: Terminal Value as % of EV | C31: =C21/C24 -> 0.77486832

Sheet SENSITIVITY ANALYSIS
B2: SENSITIVITY ANALYSIS – FAIR VALUE PER SHARE (₹)
B4: Table : Fair Value vs WACC & Terminal Growth Rate
B5: WACC → / TGR ↓ | D5: 0.095 | E5: 0.105 | F5: 0.11 | G5: 0.115 | H5: 0.125 | I5: 0.135
B6: TGR = 3.0% | D6: 1721.43 | E6: 1489.36 | F6: 1395.16 | G6: 1312.1 | H6: 1172.33 | I6: 1059.34
B7: TGR = 3.5% | D7: 1835.48 | E7: 1571.06 | F7: 1465.37 | G7: 1372.94 | H7: 1219.02 | I7: 1096.04
B8: TGR = 4.0% | D8: 1970.26 | E8: 1665.32 | F8: 1545.6 | G8: 1441.89 | H8: 1271.21 | I8: 1136.6
B9: TGR = 4.5% | D9: 2132 | E9: 1775.29 | F9: 1638.17 | G9: 1520.7 | H9: 1329.91 | I9: 1181.67
B10: TGR = 5.0% | D10: 2329.68 | E10: 1905.26 | F10: 1746.18 | G10: 1611.62 | H10: 1396.45 | I10: 1232.03
B11: TGR = 5.5% | D11: 2576.77 | E11: 2061.22 | F11: 1873.82 | G11: 1717.7 | H11: 1472.48 | I11: 1288.7
B12: TGR = 6.0% | D12: 2894.47 | E12: 2251.84 | F12: 2026.99 | G12: 1843.07 | H12: 1560.22 | I12: 1352.92
